Workbook
Name DateDeb: INFOS!$A$4
Name DateFin: INFOS!$C$4
Name zonerech: Factures!#REF!
Name zonerech: 'FacturesCALC (2)'!#REF!
Name zonerech: 'FacturesCALC (4)'!#REF!
Name zonerech: FacturesCALC!#REF!

Sheet INFOS
A3: FACTURES du
A4: =MIN(FacturesCALC!C2:C239) -> 39836 | B4: au | C4: =MAX(FacturesCALC!C2:C239) -> 40862
A5: =MIN(FacturesCALC!Q2:Q239) -> 45029 | B5: au | C5: =MAX(FacturesCALC!Q2:Q239) -> 46055 | D5: Date Facture
A6: =MIN(FacturesCALC!R2:R239) -> 45060 | B6: au | C6: =MAX(FacturesCALC!R2:R239) -> 46085 | D6: Date Échéance
A7: =A6-TODAY() -> -995 | C7: =C6-TODAY() -> 30
A8: Mettre à jour les dates de factures en cliquant sur le dessin ci-dessous

Sheet FacturesCALC
A1: NumFacture | B1: NumClient | C1: NO_Datefacture | D1: Type | E1: Acompte | F1: NO_DateEcheance | G1: Frais de Port | H1: Escompte | I1: Facture Réglée | J1: Vendeur | K1: Commission VRP réglée | L1: Avoir | M1: RemRelance | N1: CommUnitaire | O1: NO_Decalage_Date_fact | P1: NO_Decalage_DateEch | Q1: Date Facture | R1: Date Echeance Fact
A2: 2383 | B2: 1745 | C2: 39836 | D2: SORTIE | E2: 0 | F2: 39872 | G2: 0 | H2: 0 | I2: TRUE | J2: 1524 | K2: FALSE | L2: FALSE | M2: 0 | N2: 6 | O2: =DATEDIF(C2,DateFin,"d") -> 1026 | P2: =DATEDIF(F2,DateFin,"d") -> 990 | Q2: =TODAY()-O2 -> 45029 | R2: =TODAY()-P2 -> 45065
A3: 2384 | B3: 707 | C3: 39837 | D3: SORTIE | E3: 0 | F3: =C3+30 -> 39867 | G3: 0 | H3: 0 | I3: TRUE | J3: 1524 | K3: FALSE | L3: FALSE | M3: 0 | N3: 6 | O3: =DATEDIF(C3,DateFin,"d") -> 1025 | P3: =DATEDIF(F3,DateFin,"d") -> 995 | Q3: =TODAY()-O3 -> 45030 | R3: =TODAY()-P3 -> 45060
A4: 2385 | B4: 2937 | C4: 39842 | D4: SORTIE | E4: 0 | F4: =C4+30 -> 39872 | G4: 0 | H4: 0 | I4: TRUE | J4: 1524 | K4: FALSE | L4: FALSE | M4: 0 | N4: 6 | O4: =DATEDIF(C4,DateFin,"d") -> 1020 | P4: =DATEDIF(F4,DateFin,"d") -> 990 | Q4: =TODAY()-O4 -> 45035 | R4: =TODAY()-P4 -> 45065
A5: 2386 | B5: 3647 | C5: 39844 | D5: SORTIE | E5: 0 | F5: =C5+30 -> 39874 | G5: 0 | H5: 0 | I5: TRUE | J5: 640 | K5: TRUE | L5: FALSE | M5: 0 | N5: 6 | O5: =DATEDIF(C5,DateFin,"d") -> 1018 | P5: =DATEDIF(F5,DateFin,"d") -> 988 | Q5: =TODAY()-O5 -> 45037 | R5: =TODAY()-P5 -> 45067
A6: 2387 | B6: 2952 | C6: 39844 | D6: SORTIE | E6: 0 | F6: =C6+30 -> 39874 | G6: 30 | H6: 0.03 | I6: TRUE | J6: 1524 | K6: FALSE | L6: FALSE | M6: 0 | N6: 6 | O6: =DATEDIF(C6,DateFin,"d") -> 1018 | P6: =DATEDIF(F6,DateFin,"d") -> 988 | Q6: =TODAY()-O6 -> 45037 | R6: =TODAY()-P6 -> 45067
A7: 2388 | B7: 933 | C7: 39848 | D7: SORTIE | E7: 0 | F7: =C7+30 -> 39878 | G7: 0 | H7: 0 | I7: TRUE | J7: 1524 | K7: FALSE | L7: FALSE | M7: 0 | N7: 6 | O7: =DATEDIF(C7,DateFin,"d") -> 1014 | P7: =DATEDIF(F7,DateFin,"d") -> 984 | Q7: =TODAY()-O7 -> 45041 | R7: =TODAY()-P7 -> 45071
A8: 2389 | B8: 3005 | C8: 39856 | D8: SORTIE | E8: 0 | F8: =C8+30 -> 39886 | G8: 22 | H8: 0 | I8: TRUE | J8: 1524 | K8: FALSE | L8: FALSE | M8: 0 | N8: 6 | O8: =DATEDIF(C8,DateFin,"d") -> 1006 | P8: =DATEDIF(F8,DateFin,"d") -> 976 | Q8: =TODAY()-O8 -> 45049 | R8: =TODAY()-P8 -> 45079
A9: 2390 | B9: 2937 | C9: 39864 | D9: SORTIE | E9: 0 | F9: =C9+30 -> 39894 | G9: 19 | H9: 0 | I9: TRUE | J9: 1524 | K9: TRUE | L9: FALSE | M9: 0 | N9: 6 | O9: =DATEDIF(C9,DateFin,"d") -> 998 | P9: =DATEDIF(F9,DateFin,"d") -> 968 | Q9: =TODAY()-O9 -> 45057 | R9: =TODAY()-P9 -> 45087
A10: 2391 | B10: 2971 | C10: 39872 | D10: SORTIE | E10: 0 | F10: =C10+30 -> 39902 | G10: 0 | H10: 0 | I10: TRUE | J10: 640 | K10: TRUE | L10: FALSE | M10: 0 | N10: 6 | O10: =DATEDIF(C10,DateFin,"d") -> 990 | P10: =DATEDIF(F10,DateFin,"d") -> 960 | Q10: =TODAY()-O10 -> 45065 | R10: =TODAY()-P10 -> 45095
A11: 2392 | B11: 3620 | C11: 39880 | D11: SORTIE | E11: 0 | F11: =C11+30 -> 39910 | G11: 0 | H11: 0.03 | I11: TRUE | J11: 1524 | K11: FALSE | L11: FALSE | M11: 0 | N11: 6 | O11: =DATEDIF(C11,DateFin,"d") -> 982 | P11: =DATEDIF(F11,DateFin,"d") -> 952 | Q11: =TODAY()-O11 -> 45073 | R11: =TODAY()-P11 -> 45103
A12: 2393 | B12: 2421 | C12: 39888 | D12: SORTIE | E12: 0 | F12: =C12+30 -> 39918 | G12: 0 | H12: 0 | I12: TRUE | J12: 1524 | K12: FALSE | L12: FALSE | M12: 0 | N12: 6 | O12: =DATEDIF(C12,DateFin,"d") -> 974 | P12: =DATEDIF(F12,DateFin,"d") -> 944 | Q12: =TODAY()-O12 -> 45081 | R12: =TODAY()-P12 -> 45111
A13: 2394 | B13: 3659 | C13: 39896 | D13: SORTIE | E13: 0 | F13: =C13+30 -> 39926 | G13: 85 | H13: 0 | I13: TRUE | J13: 1524 | K13: FALSE | L13: FALSE | M13: 0 | N13: 6 | O13: =DATEDIF(C13,DateFin,"d") -> 966 | P13: =DATEDIF(F13,DateFin,"d") -> 936 | Q13: =TODAY()-O13 -> 45089 | R13: =TODAY()-P13 -> 45119
A14: 2395 | B14: 1277 | C14: 39904 | D14: SORTIE | E14: 500 | F14: =C14+30 -> 39934 | G14: 69 | H14: 0 | I14: TRUE | J14: 1524 | K14: FALSE | L14: FALSE | M14: 0 | N14: 6 | O14: =DATEDIF(C14,DateFin,"d") -> 958 | P14: =DATEDIF(F14,DateFin,"d") -> 928 | Q14: =TODAY()-O14 -> 45097 | R14: =TODAY()-P14 -> 45127
... A21: 2402 | B21: 2937 | C21: 39982 | D21: SORTIE | E21: 0 | F21: =C21+30 -> 40012 | G21: 0 | H21: 0 | I21: TRUE | J21: 1524 | K21: FALSE | L21: FALSE | M21: 0 | N21: 6 | O21: =DATEDIF(C21,DateFin,"d") -> 880 | P21: =DATEDIF(F21,DateFin,"d") -> 850 | Q21: =TODAY()-O21 -> 45175 | R21: =TODAY()-P21 -> 45205
A22: 2403 | B22: 1095 | C22: 39984 | D22: SORTIE | E22: 0 | F22: 40025 | G22: 0 | H22: 0 | I22: TRUE | J22: 1524 | K22: FALSE | L22: FALSE | M22: 0 | N22: 6 | O22: =DATEDIF(C22,DateFin,"d") -> 878 | P22: =DATEDIF(F22,DateFin,"d") -> 837 | Q22: =TODAY()-O22 -> 45177 | R22: =TODAY()-P22 -> 45218
A23: 2404 | B23: 2937 | C23: 40002 | D23: SORTIE | E23: 0 | F23: =C23+30 -> 40032 | G23: 0 | H23: 0 | I23: TRUE | J23: 1524 | K23: FALSE | L23: FALSE | M23: 0 | N23: 6 | O23: =DATEDIF(C23,DateFin,"d") -> 860 | P23: =DATEDIF(F23,DateFin,"d") -> 830 | Q23: =TODAY()-O23 -> 45195 | R23: =TODAY()-P23 -> 45225
A24: 2405 | B24: 798 | C24: 40002 | D24: SORTIE | E24: 0 | F24: =C24+30 -> 40032 | G24: 0 | H24: 0 | I24: TRUE | J24: 1524 | K24: FALSE | L24: FALSE | M24: 0 | N24: 6 | O24: =DATEDIF(C24,DateFin,"d") -> 860 | P24: =DATEDIF(F24,DateFin,"d") -> 830 | Q24: =TODAY()-O24 -> 45195 | R24: =TODAY()-P24 -> 45225
A25: 2406 | B25: 1472 | C25: 40011 | D25: SORTIE | E25: 0 | F25: =C25+30 -> 40041 | G25: 0 | H25: 0 | I25: TRUE | J25: 640 | K25: TRUE | L25: FALSE | M25: 0 | N25: 6 | O25: =DATEDIF(C25,DateFin,"d") -> 851 | P25: =DATEDIF(F25,DateFin,"d") -> 821 | Q25: =TODAY()-O25 -> 45204 | R25: =TODAY()-P25 -> 45234
A26: 2407 | B26: 1277 | C26: 40015 | D26: SORTIE | E26: 0 | F26: =C26+30 -> 40045 | G26: 30 | H26: 0.03 | I26: TRUE | J26: 1524 | K26: FALSE | L26: FALSE | M26: 0 | N26: 6 | O26: =DATEDIF(C26,DateFin,"d") -> 847 | P26: =DATEDIF(F26,DateFin,"d") -> 817 | Q26: =TODAY()-O26 -> 45208 | R26: =TODAY()-P26 -> 45238
A27: 2408 | B27: 3624 | C27: 40016 | D27: SORTIE | E27: 0 | F27: =C27+30 -> 40046 | G27: 0 | H27: 0 | I27: TRUE | J27: 1524 | K27: FALSE | L27: FALSE | M27: 0 | N27: 6 | O27: =DATEDIF(C27,DateFin,"d") -> 846 | P27: =DATEDIF(F27,DateFin,"d") -> 816 | Q27: =TODAY()-O27 -> 45209 | R27: =TODAY()-P27 -> 45239
A28: 2409 | B28: 3638 | C28: 40022 | D28: SORTIE | E28: 0 | F28: =C28+30 -> 40052 | G28: 22 | H28: 0 | I28: TRUE | J28: 1524 | K28: FALSE | L28: FALSE | M28: 0 | N28: 6 | O28: =DATEDIF(C28,DateFin,"d") -> 840 | P28: =DATEDIF(F28,DateFin,"d") -> 810 | Q28: =TODAY()-O28 -> 45215 | R28: =TODAY()-P28 -> 45245
A29: 2410 | B29: 1559 | C29: 40022 | D29: SORTIE | E29: 0 | F29: =C29+30 -> 40052 | G29: 19 | H29: 0 | I29: TRUE | J29: 1524 | K29: TRUE | L29: FALSE | M29: 0 | N29: 6 | O29: =DATEDIF(C29,DateFin,"d") -> 840 | P29: =DATEDIF(F29,DateFin,"d") -> 810 | Q29: =TODAY()-O29 -> 45215 | R29: =TODAY()-P29 -> 45245
A30: 2411 | B30: 2971 | C30: 40025 | D30: SORTIE | E30: 0 | F30: =C30+30 -> 40055 | G30: 0 | H30: 0 | I30: TRUE | J30: 640 | K30: TRUE | L30: FALSE | M30: 0 | N30: 6 | O30: =DATEDIF(C30,DateFin,"d") -> 837 | P30: =DATEDIF(F30,DateFin,"d") -> 807 | Q30: =TODAY()-O30 -> 45218 | R30: =TODAY()-P30 -> 45248
A31: 2412 | B31: 3620 | C31: 40060 | D31: SORTIE | E31: 0 | F31: =C31+30 -> 40090 | G31: 0 | H31: 0.03 | I31: TRUE | J31: 1524 | K31: FALSE | L31: FALSE | M31: 0 | N31: 6 | O31: =DATEDIF(C31,DateFin,"d") -> 802 | P31: =DATEDIF(F31,DateFin,"d") -> 772 | Q31: =TODAY()-O31 -> 45253 | R31: =TODAY()-P31 -> 45283
A32: 2413 | B32: 2421 | C32: 40078 | D32: SORTIE | E32: 0 | F32: =C32+30 -> 40108 | G32: 0 | H32: 0 | I32: TRUE | J32: 1524 | K32: FALSE | L32: FALSE | M32: 0 | N32: 6 | O32: =DATEDIF(C32,DateFin,"d") -> 784 | P32: =DATEDIF(F32,DateFin,"d") -> 754 | Q32: =TODAY()-O32 -> 45271 | R32: =TODAY()-P32 -> 45301
A33: 2414 | B33: 3659 | C33: 40074 | D33: SORTIE | E33: 0 | F33: =C33+30 -> 40104 | G33: 85 | H33: 0 | I33: TRUE | J33: 1524 | K33: FALSE | L33: FALSE | M33: 0 | N33: 6 | O33: =DATEDIF(C33,DateFin,"d") -> 788 | P33: =DATEDIF(F33,DateFin,"d") -> 758 | Q33: =TODAY()-O33 -> 45267 | R33: =TODAY()-P33 -> 45297
A34: 2415 | B34: 2829 | C34: 40088 | D34: SORTIE | E34: 500 | F34: =C34+30 -> 40118 | G34: 69 | H34: 0 | I34: TRUE | J34: 1524 | K34: FALSE | L34: FALSE | M34: 0 | N34: 6 | O34: =DATEDIF(C34,DateFin,"d") -> 774 | P34: =DATEDIF(F34,DateFin,"d") -> 744 | Q34: =TODAY()-O34 -> 45281 | R34: =TODAY()-P34 -> 45311
... A224: 2605 | B224: 798 | C224: 40757 | D224: SORTIE | E224: 0 | F224: =C224+30 -> 40787 | G224: 0 | H224: 0.3 | I224: FALSE | J224: 1524 | K224: FALSE | L224: FALSE | M224: 0 | N224: 6 | O224: =DATEDIF(C224,DateFin,"d") -> 105 | P224: =DATEDIF(F224,DateFin,"d") -> 75 | Q224: =TODAY()-O224 -> 45950 | R224: =TODAY()-P224 -> 45980
A225: 2606 | B225: 2829 | C225: 40764 | D225: SORTIE | E225: 0 | F225: =C225+60 -> 40824 | G225: 0 | H225: 0 | I225: TRUE | J225: 1524 | K225: FALSE | L225: FALSE | M225: 0 | N225: 6 | O225: =DATEDIF(C225,DateFin,"d") -> 98 | P225: =DATEDIF(F225,DateFin,"d") -> 38 | Q225: =TODAY()-O225 -> 45957 | R225: =TODAY()-P225 -> 46017
A226: 2607 | B226: 2962 | C226: 40771 | D226: SORTIE | E226: 0 | F226: =C226+30 -> 40801 | G226: 46 | H226: 0.2 | I226: TRUE | J226: 1524 | K226: TRUE | L226: FALSE | M226: 0 | N226: 6 | O226: =DATEDIF(C226,DateFin,"d") -> 91 | P226: =DATEDIF(F226,DateFin,"d") -> 61 | Q226: =TODAY()-O226 -> 45964 | R226: =TODAY()-P226 -> 45994
A227: 2608 | B227: 1156 | C227: 40778 | D227: SORTIE | E227: 0 | F227: =C227+30 -> 40808 | G227: 29.5 | H227: 0 | I227: TRUE | J227: 1524 | K227: FALSE | L227: FALSE | M227: 0 | N227: 6 | O227: =DATEDIF(C227,DateFin,"d") -> 84 | P227: =DATEDIF(F227,DateFin,"d") -> 54 | Q227: =TODAY()-O227 -> 45971 | R227: =TODAY()-P227 -> 46001
A228: 2609 | B228: 2478 | C228: 40785 | D228: SORTIE | E228: 0 | F228: =C228+30 -> 40815 | G228: 14.5 | H228: 0 | I228: FALSE | J228: 640 | K228: FALSE | L228: FALSE | M228: 0 | N228: 6 | O228: =DATEDIF(C228,DateFin,"d") -> 77 | P228: =DATEDIF(F228,DateFin,"d") -> 47 | Q228: =TODAY()-O228 -> 45978 | R228: =TODAY()-P228 -> 46008
A229: 2610 | B229: 2319 | C229: 40792 | D229: SORTIE | E229: 0 | F229: =C229+30 -> 40822 | G229: 0 | H229: 0.3 | I229: TRUE | J229: 1524 | K229: FALSE | L229: FALSE | M229: 0 | N229: 6 | O229: =DATEDIF(C229,DateFin,"d") -> 70 | P229: =DATEDIF(F229,DateFin,"d") -> 40 | Q229: =TODAY()-O229 -> 45985 | R229: =TODAY()-P229 -> 46015
A230: 2611 | B230: 2937 | C230: 40799 | D230: SORTIE | E230: 0 | F230: =C230+60 -> 40859 | G230: 0 | H230: 0.3 | I230: FALSE | J230: 1524 | K230: FALSE | L230: FALSE | M230: 0 | N230: 6 | O230: =DATEDIF(C230,DateFin,"d") -> 63 | P230: =DATEDIF(F230,DateFin,"d") -> 3 | Q230: =TODAY()-O230 -> 45992 | R230: =TODAY()-P230 -> 46052
A231: 2612 | B231: 1482 | C231: 40806 | D231: SORTIE | E231: 0 | F231: =C231+30 -> 40836 | G231: 36 | H231: 0 | I231: TRUE | J231: 640 | K231: TRUE | L231: FALSE | M231: 0 | N231: 6 | O231: =DATEDIF(C231,DateFin,"d") -> 56 | P231: =DATEDIF(F231,DateFin,"d") -> 26 | Q231: =TODAY()-O231 -> 45999 | R231: =TODAY()-P231 -> 46029
A232: 2613 | B232: 798 | C232: 40813 | D232: SORTIE | E232: 0 | F232: =C232+30 -> 40843 | G232: 0 | H232: 0.3 | I232: FALSE | J232: 1524 | K232: FALSE | L232: FALSE | M232: 0 | N232: 6 | O232: =DATEDIF(C232,DateFin,"d") -> 49 | P232: =DATEDIF(F232,DateFin,"d") -> 19 | Q232: =TODAY()-O232 -> 46006 | R232: =TODAY()-P232 -> 46036
A233: 2614 | B233: 798 | C233: 40820 | D233: SORTIE | E233: 0 | F233: =C233+60 -> 40880 | G233: 0 | H233: 0 | I233: TRUE | J233: 1524 | K233: TRUE | L233: FALSE | M233: 0 | N233: 6 | O233: =DATEDIF(C233,DateFin,"d") -> 42 | P233: =O233-30 -> 12 | Q233: =TODAY()-O233 -> 46013 | R233: =TODAY()-P233 -> 46043
A234: 2615 | B234: 27 | C234: 40827 | D234: SORTIE | E234: 0 | F234: =C234+30 -> 40857 | G234: 0 | H234: 0.2 | I234: TRUE | J234: 1524 | K234: FALSE | L234: FALSE | M234: 0 | N234: 6 | O234: =DATEDIF(C234,DateFin,"d") -> 35 | P234: =O234-30 -> 5 | Q234: =TODAY()-O234 -> 46020 | R234: =TODAY()-P234 -> 46050
A235: 2616 | B235: 3647 | C235: 40834 | D235: SORTIE | E235: 0 | F235: =C235+30 -> 40864 | G235: 19 | H235: 0 | I235: TRUE | J235: 1524 | K235: FALSE | L235: FALSE | M235: 0 | N235: 6 | O235: =DATEDIF(C235,DateFin,"d") -> 28 | P235: =O235-30 -> -2 | Q235: =TODAY()-O235 -> 46027 | R235: =TODAY()-P235 -> 46057
...

Sheet DetFactures
A1: NumLignDetFact | B1: NumFacture | C1: Ref_produit | D1: Quantité | E1: Remise Eur
A2: 1 | B2: FA-2383 | C2: INJOBP683B | D2: 1 | E2: 0
A3: 2 | B3: FA-2383 | C3: SCRAPT10010045 | D3: 3 | E3: 0
A4: 3 | B4: FA-2383 | C4: SCRAPT1409076 | D4: 10 | E4: 0
A5: 4 | B5: FA-2383 | C5: SCRAPT1609076 | D5: 12 | E5: 0
A6: 5 | B6: FA-2383 | C6: SCRAPT1809076 | D6: 7 | E6: 0
A7: 6 | B7: FA-2383 | C7: SDCSWW | D7: 14 | E7: 0
A8: 7 | B8: FA-2384 | C8: IC3B | D8: 100 | E8: 0
A9: 8 | B9: FA-2384 | C9: IC5E | D9: 100 | E9: 0
A10: 9 | B10: FA-2384 | C10: IC5B | D10: 100 | E10: 0
A11: 10 | B11: FA-2384 | C11: INJOBP683B | D11: 100 | E11: 0
A12: 11 | B12: FA-2384 | C12: SCRAPBS1GD | D12: 20 | E12: 0
A13: 12 | B13: FA-2384 | C13: SCRAPBS1SD | D13: 20 | E13: 0
... A2091: 2099 | B2091: FA-2620 | C2091: INBAN064 | D2091: 280 | E2091: 0

Sheet Clients
A1: NumClient | B1: Nom de la société | C1: Adress1 | D1: Adress1b | E1: Code postal | F1: Ville | G1: Réfpays | H1: Civilite1 | I1: Type Client | J1: N° de TVA CEE | K1: Datecreation
A2: 7 | B2: Personne 000 | C2: 1 rue de Perceval | E2: 75014 | F2: PARIS | G2: France | I2: PARTICULIER | K2: 37104
A3: 8 | B3: Personne 001 | C3: 13 rue Scipion | E3: 75005 | F3: PARIS | G3: France | I3: PARTICULIER | K3: 37104
A4: 9 | B4: Personne 002 | C4: 25 rue du Faubourg Poissonière | E4: 75009 | F4: PARIS | G4: France | I4: PARTICULIER | K4: 37104
A5: 10 | B5: Personne 003 | C5: 244 rue de Rivoli | E5: 75001 | F5: PARIS | G5: France | I5: PARTICULIER | K5: 37104
A6: 11 | B6: Personne 004 | C6: 1 rue Jean Jaurès | E6: 78600 | F6: LE MESNIL le ROI | G6: France | I6: PARTICULIER | K6: 37104
A7: 12 | B7: Personne 005 | C7: 11 bis rue Cantin | E7: 92400 | F7: COURBEVOIE | G7: France | I7: PARTICULIER | K7: 37104
A8: 15 | B8: Personne 006 | C8: 4 Bvd de Port Royal | E8: 75005 | F8: PARIS | G8: France | I8: PARTICULIER | K8: 37104
A9: 19 | B9: Personne 007 | C9: Champ de la Perraudière | E9: 49170 | F9: St MARTIN DU FOUILLOUX | G9: France | I9: PARTICULIER | K9: 37104
A10: 20 | B10: Personne 008 | C10: 147 bis rue de Silly | E10: 92100 | F10: BOULOGNE-BILLANCOURT | G10: France | I10: PARTICULIER | K10: 37104
A11: 21 | B11: Personne 009 | C11: 14 rue Bridaine | E11: 75017 | F11: PARIS | G11: France | I11: PARTICULIER | K11: 37104
A12: 22 | B12: Personne 010 | C12: 11 rue Emile Dubois | E12: 75014 | F12: PARIS | G12: France | I12: PARTICULIER | K12: 37104
A13: 23 | B13: Personne 011 | C13: 9 rue Dareau | E13: 75014 | F13: PARIS | G13: France | H13: Madame | I13: PARTICULIER | K13: 37104
A14: 25 | B14: Personne 012 | C14: 1 rue Félix | E14: 69003 | F14: LYON | G14: France | I14: PARTICULIER | K14: 37104
A15: 26 | B15: Personne 013 | C15: 1 allée des Meilliers | E15: 94500 | F15: CHAMPIGNY sur MARNE | G15: France | I15: PARTICULIER | K15: 37104
A16: 27 | B16: Personne 014 | C16: 32 avenue E. Boutroux | E16: 92120 | F16: MONTROUGE | G16: France | I16: PARTICULIER | K16: 37104
A17: 33 | B17: Personne 015 | C17: 2bis avenue des Abeilles | E17: 77270 | F17: VILLEPARISIS | G17: France | I17: PARTICULIER | K17: 37104
A18: 38 | B18: Personne 016 | C18: 25 rue St Vincent de Paul | E18: 75010 | F18: PARIS | G18: France | I18: PARTICULIER | K18: 37104
A19: 42 | B19: Personne 017 | C19: 63 rue Charles Nodier | E19: 93500 | F19: PANTIN | G19: France | I19: PARTICULIER | K19: 37104
A20: 43 | B20: Personne 018 | C20: 14 rue Bleue | E20: 75009 | F20: PARIS | G20: France | I20: PARTICULIER | K20: 37104
A21: 48 | B21: Personne 019 | C21: 22 rue Condorcet | E21: 75009 | F21: PARIS | G21: France | I21: PARTICULIER | K21: 37104
A22: 51 | B22: Personne 020 | C22: 4 square Ernest Defay | E22: 78280 | F22: GUYANCOURT | G22: France | I22: PARTICULIER | K22: 37104
A23: 53 | B23: Personne 021 | C23: 143 rue d'Alesia | E23: 75014 | F23: PARIS | G23: France | I23: PARTICULIER | K23: 37104
A24: 56 | B24: Personne 022 | C24: 22 rue Melingue | E24: 75019 | F24: PARIS | G24: France | I24: PARTICULIER | K24: 37104
A25: 61 | B25: Personne 023 | C25: 33 rue Brochant | E25: 75017 | F25: PARIS | G25: France | I25: PARTICULIER | K25: 37104
... A33: 78 | B33: Personne 031 | C33: 23 rue de Cronstadt | E33: 75015 | F33: PARIS | G33: France | I33: PARTICULIER | K33: 37104
A34: 79 | B34: Personne 032 | C34: Bat C | D34: 56 rue du Chemin Vert | E34: 92100 | F34: BOULOGNE | G34: France | I34: PARTICULIER | K34: 37104
A35: 82 | B35: Personne 033 | C35: 1 rue Théophile Roussel | E35: 75012 | F35: PARIS | G35: France | H35: Madame | I35: PARTICULIER | K35: 37104
A36: 83 | B36: Personne 034 | C36: 17/19 rue Frédéric Chopin | D36: Bat B | E36: 92160 | F36: ANTONY | G36: France | I36: PARTICULIER | K36: 37104
A37: 86 | B37: Personne 035 | C37: 4 rue Georges Auric | E37: 75019 | F37: PARIS | G37: France | I37: PARTICULIER | K37: 37104
A38: 88 | B38: Personne 036 | C38: 37 rue de la Plaine | E38: 75020 | F38: PARIS | G38: France | I38: PARTICULIER | K38: 37104
A39: 91 | B39: Personne 037 | C39: 32 Bd de Reuilly | E39: 75012 | F39: PARIS | G39: France | I39: PARTICULIER | K39: 37104
A40: 92 | B40: Personne 038 | C40: 22 rue Mélingue | E40: 75019 | F40: PARIS | G40: France | I40: PARTICULIER | K40: 37104
A41: 99 | B41: Personne 039 | C41: 2 rue de Colmar | E41: 94300 | F41: VINCENNES | G41: France | I41: PARTICULIER | K41: 37104
A42: 101 | B42: Personne 040 | C42: 17 rue Lagrange | E42: 75005 | F42: PARIS | G42: France | I42: PARTICULIER | K42: 37104
A43: 102 | B43: Personne 041 | C43: 3 rue Soufflot | E43: 75005 | F43: PARIS | G43: France | I43: PARTICULIER | K43: 37104
A44: 108 | B44: Personne 042 | C44: 54 rue de la Verrerie | E44: 75004 | F44: PARIS | G44: France | I44: PARTICULIER | K44: 37104
A45: 109 | B45: Personne 043 | C45: 38 avenue Daumesnil | E45: 75012 | F45: PARIS | G45: France | I45: PARTICULIER | K45: 37104
A46: 111 | B46: Personne 044 | C46: 58 rue Charlot | E46: 75003 | F46: PARIS | G46: France | I46: PARTICULIER | K46: 37104
A47: 114 | B47: Personne 045 | C47: 47 avenue du docteur Arnol Metter | E47: 75012 | F47: PARIS | G47: France | I47: PARTICULIER | K47: 37104
...

Sheet Articles
A1: NumArticle | B1: Origine | C1: Famille | D1: Catégorie | E1: MatPrincipale | F1: DescriptionProduit | G1: Taille | H1: Prixrevient | I1: Prix Revendeur | J1: Prix Public | K1: Prix Ex Works | L1: Min Qte
A2: ARCHYS | B2: Inde | C2: Petit mobilier | D2: Chaise / Fauteuil / Banc / Tabouret | E2: Métal | F2: Tabouret de bar tournant en métal et bois recyclé polychromé | G2: 37 x 42 x 80 | H2: 80.9457 | I2: 249 | J2: 545 | K2: 64.5161 | L2: 1
A3: BOUFFADOU | B3: Inde | C3: Accessoires | D3: Accessoires de cheminée | E3: Fer forgé | F3: Bouffadou / tisonnier forgé à la main avec poignées en teck (carton de 10) | G3: 95 x 3 x 3 | H3: 5.4526 | I3: 22 | J3: 49 | K3: 4.3621 | L3: 10
A4: EMI001 | B4: Inde | C4: Grand Meubles | D4: Bibliothèque / Vitrine / Etagère | E4: Tek birman | F4: Ancienne vitrine en tek birman avec 2 portes vitrées coulissantes et son marquage "Air voice" et sa patine verte d'origine | G4: 121 x 30 x 60 | H4: 60.9848 | I4: 235 | J4: 585 | K4: 53.0303 | L4: 1
A5: EMI002 | B5: Inde | C5: Grand Meubles | D5: Bureau / Secrétaire / Bar | E5: Tek birman | F5: Bar en bois polychromé recyclé avec arrondi vitré | G5: 140 x 51 x 98 | H5: 156.8182 | I5: 470 | J5: 1175 | K5: 136.3636 | L5: 1
A6: EMI003 | B6: Inde | C6: Grand Meubles | D6: Vaisselier / Buffet / Garde-manger | E6: Tek birman | F6: Ancien vaisselier en tek birman 2 portes vitrées avec sa patine verte d'origine | G6: 94 x 42 x 126 | H6: 121.9697 | I6: 390 | J6: 975 | K6: 106.0606 | L6: 1
A7: EMI004 | B7: Inde | C7: Grand Meubles | D7: Vaisselier / Buffet / Garde-manger | E7: Tek birman | F7: Ancien garde-manger en tek birman avec 2 double portes vitrées et sa patine turquoise d'origine | G7: 93 x 36 x 156 | H7: 104.5455 | I7: 385 | J7: 960 | K7: 90.9091 | L7: 1
A8: EMI005 | B8: Inde | C8: Grand Meubles | D8: Bibliothèque / Vitrine / Etagère | E8: Tek birman | F8: Ancienne étagère de cuisine en tek birman avec sa patine turquoise d'origine | G8: 95 x 40 x 140 | H8: 60.9848 | I8: 225 | J8: 560 | K8: 53.0303 | L8: 1
A9: IC1B | B9: Iran | C9: Arts de la table | D9: Bol | E9: Céramique | F9: Bol à céréales motif poisson /coloris bleu (conditionné par 8) | G9: Diam : 14 / H : 6 | H9: 2.12 | I9: 5.15 | J9: 14 | K9: 1.52 | L9: 8
A10: IC1E | B10: Iran | C10: Arts de la table | D10: Bol | E10: Céramique | F10: Bol à céréales motif poisson /coloris écru (conditionné par 8) | G10: Diam : 14 / H : 6 | H10: 2.12 | I10: 5.15 | J10: 14 | K10: 1.52 | L10: 8
A11: IC1G | B11: Iran | C11: Arts de la table | D11: Bol | E11: Céramique | F11: Bol à céréales motif poisson /coloris vert (conditionné par 8) | G11: Diam : 14 / H : 6 | H11: 2.12 | I11: 5.15 | J11: 14 | K11: 1.52 | L11: 1
A12: IC1T | B12: Iran | C12: Arts de la table | D12: Bol | E12: Céramique | F12: Bol à céréales motif poisson /coloris turquoise (conditionné par 8) | G12: Diam : 14 / H : 6 | H12: 2.12 | I12: 5.15 | J12: 14 | K12: 1.52 | L12: 1
A13: IC1Y | B13: Iran | C13: Arts de la table | D13: Bol | E13: Céramique | F13: Bol à céréales motif poisson /coloris jaune (conditionné par 8) | G13: Diam : 14 / H : 6 | H13: 2.12 | I13: 5.15 | J13: 14 | K13: 1.52 | L13: 1
... A185: INK156 | B185: Inde | C185: Grand Meubles | D185: Vaisselier / Buffet / Garde-manger | E185: Tek birman | F185: Ancien vaisselier en tek avec 2 portes ( 6 vitres) + 2 tiroirs + 1 corniche supérieure et sa patine turquoise d'origine | G185: 74 x 34 x 137 | H185: 104.258 | I185: 339 | J185: 745 | K185: 83.0968 | L185: 1
A186: INK157 | B186: Inde | C186: Petit mobilier | D186: Chaise / Fauteuil / Banc / Tabouret | E186: Tek birman | F186: Ancien pupitre et chaise d'écolier en tek ( prix du set chaise + pupitre) | H186: 20.3983 | I186: 75 | J186: 165 | K186: 16.2581 | L186: 1
A187: INK158 | B187: Inde | C187: Grand Meubles | D187: Commode / Coiffeuse | E187: Tek birman | F187: Ancienne commode en tek avec 5 tiroirs | G187: 90 x 48 x 110 | H187: 124.6563 | I187: 359 | J187: 769 | K187: 99.3548 | L187: 1
A188: INK159 | B188: Inde | C188: Grand Meubles | D188: Commode / Coiffeuse | E188: Tek birman | F188: Ancienne commode en tek avec 4 tiroirs | G188: 97 x 45 x 76 | H188: 108.791 | I188: 315 | J188: 690 | K188: 86.7097 | L188: 1
A189: INK160 | B189: Inde | C189: Grand Meubles | D189: Table / Console / Guéridon | E189: Tek birman | F189: Ancienne table basse en tek avec 2 tiroirs | G189: 126 x 79 x 46 | H189: 56.662 | I189: 195 | J189: 419 | K189: 45.1613 | L189: 1
A190: INK161 | B190: Inde | C190: Grand Meubles | D190: Table / Console / Guéridon | E190: Tek birman | F190: Ancienne table basse en tek avec 3 tiroirs | G190: 157 x 74 x 56 | H190: 101.9916 | I190: 299 | J190: 649 | K190: 81.2903 | L190: 1
A191: INK162 | B191: Inde | C191: Grand Meubles | D191: Vaisselier / Buffet / Garde-manger | E191: Tek birman | F191: Ancien buffet en tek avec 3 portes + 3 tiroirs | G191: Assortiment | H191: 126.9228 | I191: 399 | J191: 875 | K191: 101.1613 | L191: 1
A192: INK163 | B192: Inde | C192: Grand Meubles | D192: Commode / Coiffeuse | E192: Tek birman | F192: Ancienne commode en tek avec 3 tiroirs | G192: 93 x 46 x 90 | H192: 113.324 | I192: 325 | J192: 715 | K192: 90.3226 | L192: 1
A193: INK164 | B193: Inde | C193: Grand Meubles | D193: Vaisselier / Buffet / Garde-manger | E193: Tek birman | F193: Ancien vaisselier double corps en tek avec 5 portes ( 12 vitres) + 3 tiroirs / légèrement cérusé écru | G193: 140 x 59 x 158 | H193: 176.7854 | I193: 595 | J193: 1299 | K193: 140.9032 | L193: 1
A194: INK165 | B194: Inde | C194: Grand Meubles | D194: Bibliothèque / Vitrine / Etagère | E194: Tek birman | F194: Ancien étagère d'angle en tek avec 2 portes vitrées | G194: 45 x 20 x 173 | H194: 56.662 | I194: 159 | J194: 349 | K194: 45.1613 | L194: 1
A195: INK166 | B195: Inde | C195: Petit mobilier | D195: Porte revue / Presse livre | E195: Tek birman | F195: Ancien banc-pupitre d'écolier en tek avec structure métallique | G195: 92 x 63 x 67 | H195: 63.4614 | I195: 215 | J195: 450 | K195: 50.5806 | L195: 1
A196: INK167 | B196: Inde | C196: Grand Meubles | D196: Meuble Télé / Hi-fi | E196: Tek birman | F196: Ancien meuble radio en tek avec 3 portes vitrées / porte vitrée supérieure coulissante-escamotable/ idéal en meuble hi-fi / clapets arrière prévus pour passage fils | G196: 90 x 39 x 167 | H196: 101.9916 | I196: 349 | J196: 750 | K196: 81.2903 | L196: 1
A197: INK168 | B197: Inde | C197: Grand Meubles | D197: Meuble Télé / Hi-fi | E197: Tek birman | F197: Ancien meuble bas en tek avec 2 étagères + 6 tiroirs / idéal en meuble télé / clapets arrière prévus pour passage fils | G197: 188 x 43 x 72 | H197: 124.6563 | I197: 349 | J197: 750 | K197: 99.3548 | L197: 1
A198: INK169 | B198: Inde | C198: Grand Meubles | D198: Vaisselier / Buffet / Garde-manger | E198: Tek birman | F198: Ancien meuble à chaussures en tek / idéal au pied au pied d'un lit double | G198: 182 x 28 x 28 | H198: 33.9972 | I198: 105 | J198: 229 | K198: 27.0968 | L198: 1
... A570: SWS5H | B570: Indonésie | C570: Accessoires | D570: Patère / Equerre / Bouton de porte | E570: Bois tropical | F570: Patère 5 crochets avec étagère en bois polychromé recyclé | G570: 92 x 10 x 32 | H570: 21.0833 | I570: 75 | J570: 185 | K570: 18.3333 | L570: 1

Sheet FacturesCALC (2)
A1: NumFacture | B1: NumClient | C1: NO_Datefacture | D1: Type | E1: Acompte | F1: NO_DateEcheance | G1: Frais de Port | H1: Escompte | I1: Facture Réglée | J1: Vendeur | K1: Commission VRP réglée | L1: Avoir | M1: RemRelance | N1: CommUnitaire | O1: NO_Decalage_Date_fact | P1: NO_Decalage_DateEch | Q1: Date Facture | R1: Date Echeance Fact
A2: 2383 | B2: 1745 | C2: 39836 | D2: SORTIE | E2: 0 | F2: 39872 | G2: 0 | H2: 0 | I2: TRUE | J2: 1524 | K2: FALSE | L2: FALSE | M2: 0 | N2: 6 | O2: =DATEDIF(C2,DateFin,"d") -> 1026 | P2: =DATEDIF(F2,DateFin,"d") -> 990 | Q2: =TODAY()-O2 -> 45029 | R2: =TODAY()-P2 -> 45065
A3: 2384 | B3: 707 | C3: 39837 | D3: SORTIE | E3: 0 | F3: =C3+30 -> 39867 | G3: 0 | H3: 0 | I3: TRUE | J3: 1524 | K3: FALSE | L3: FALSE | M3: 0 | N3: 6 | O3: =DATEDIF(C3,DateFin,"d") -> 1025 | P3: =DATEDIF(F3,DateFin,"d") -> 995 | Q3: =TODAY()-O3 -> 45030 | R3: =TODAY()-P3 -> 45060
A4: 2385 | B4: 2937 | C4: 39842 | D4: SORTIE | E4: 0 | F4: =C4+30 -> 39872 | G4: 0 | H4: 0 | I4: TRUE | J4: 1524 | K4: FALSE | L4: FALSE | M4: 0 | N4: 6 | O4: =DATEDIF(C4,DateFin,"d") -> 1020 | P4: =DATEDIF(F4,DateFin,"d") -> 990 | Q4: =TODAY()-O4 -> 45035 | R4: =TODAY()-P4 -> 45065
A5: 2386 | B5: 3647 | C5: 39844 | D5: SORTIE | E5: 0 | F5: =C5+30 -> 39874 | G5: 0 | H5: 0 | I5: TRUE | J5: 640 | K5: TRUE | L5: FALSE | M5: 0 | N5: 6 | O5: =DATEDIF(C5,DateFin,"d") -> 1018 | P5: =DATEDIF(F5,DateFin,"d") -> 988 | Q5: =TODAY()-O5 -> 45037 | R5: =TODAY()-P5 -> 45067
A6: 2387 | B6: 2952 | C6: 39844 | D6: SORTIE | E6: 0 | F6: =C6+30 -> 39874 | G6: 30 | H6: 0.03 | I6: TRUE | J6: 1524 | K6: FALSE | L6: FALSE | M6: 0 | N6: 6 | O6: =DATEDIF(C6,DateFin,"d") -> 1018 | P6: =DATEDIF(F6,DateFin,"d") -> 988 | Q6: =TODAY()-O6 -> 45037 | R6: =TODAY()-P6 -> 45067
A7: 2388 | B7: 933 | C7: 39848 | D7: SORTIE | E7: 0 | F7: =C7+30 -> 39878 | G7: 0 | H7: 0 | I7: TRUE | J7: 1524 | K7: FALSE | L7: FALSE | M7: 0 | N7: 6 | O7: =DATEDIF(C7,DateFin,"d") -> 1014 | P7: =DATEDIF(F7,DateFin,"d") -> 984 | Q7: =TODAY()-O7 -> 45041 | R7: =TODAY()-P7 -> 45071
A8: 2389 | B8: 3005 | C8: 39856 | D8: SORTIE | E8: 0 | F8: =C8+30 -> 39886 | G8: 22 | H8: 0 | I8: TRUE | J8: 1524 | K8: FALSE | L8: FALSE | M8: 0 | N8: 6 | O8: =DATEDIF(C8,DateFin,"d") -> 1006 | P8: =DATEDIF(F8,DateFin,"d") -> 976 | Q8: =TODAY()-O8 -> 45049 | R8: =TODAY()-P8 -> 45079
A9: 2390 | B9: 2937 | C9: 39864 | D9: SORTIE | E9: 0 | F9: =C9+30 -> 39894 | G9: 19 | H9: 0 | I9: TRUE | J9: 1524 | K9: TRUE | L9: FALSE | M9: 0 | N9: 6 | O9: =DATEDIF(C9,DateFin,"d") -> 998 | P9: =DATEDIF(F9,DateFin,"d") -> 968 | Q9: =TODAY()-O9 -> 45057 | R9: =TODAY()-P9 -> 45087
A10: 2391 | B10: 2971 | C10: 39872 | D10: SORTIE | E10: 0 | F10: =C10+30 -> 39902 | G10: 0 | H10: 0 | I10: TRUE | J10: 640 | K10: TRUE | L10: FALSE | M10: 0 | N10: 6 | O10: =DATEDIF(C10,DateFin,"d") -> 990 | P10: =DATEDIF(F10,DateFin,"d") -> 960 | Q10: =TODAY()-O10 -> 45065 | R10: =TODAY()-P10 -> 45095
A11: 2392 | B11: 3620 | C11: 39880 | D11: SORTIE | E11: 0 | F11: =C11+30 -> 39910 | G11: 0 | H11: 0.03 | I11: TRUE | J11: 1524 | K11: FALSE | L11: FALSE | M11: 0 | N11: 6 | O11: =DATEDIF(C11,DateFin,"d") -> 982 | P11: =DATEDIF(F11,DateFin,"d") -> 952 | Q11: =TODAY()-O11 -> 45073 | R11: =TODAY()-P11 -> 45103
A12: 2393 | B12: 2421 | C12: 39888 | D12: SORTIE | E12: 0 | F12: =C12+30 -> 39918 | G12: 0 | H12: 0 | I12: TRUE | J12: 1524 | K12: FALSE | L12: FALSE | M12: 0 | N12: 6 | O12: =DATEDIF(C12,DateFin,"d") -> 974 | P12: =DATEDIF(F12,DateFin,"d") -> 944 | Q12: =TODAY()-O12 -> 45081 | R12: =TODAY()-P12 -> 45111
A13: 2394 | B13: 3659 | C13: 39896 | D13: SORTIE | E13: 0 | F13: =C13+30 -> 39926 | G13: 85 | H13: 0 | I13: TRUE | J13: 1524 | K13: FALSE | L13: FALSE | M13: 0 | N13: 6 | O13: =DATEDIF(C13,DateFin,"d") -> 966 | P13: =DATEDIF(F13,DateFin,"d") -> 936 | Q13: =TODAY()-O13 -> 45089 | R13: =TODAY()-P13 -> 45119
A14: 2395 | B14: 1277 | C14: 39904 | D14: SORTIE | E14: 500 | F14: =C14+30 -> 39934 | G14: 69 | H14: 0 | I14: TRUE | J14: 1524 | K14: FALSE | L14: FALSE | M14: 0 | N14: 6 | O14: =DATEDIF(C14,DateFin,"d") -> 958 | P14: =DATEDIF(F14,DateFin,"d") -> 928 | Q14: =TODAY()-O14 -> 45097 | R14: =TODAY()-P14 -> 45127
... A21: 2402 | B21: 2937 | C21: 39982 | D21: SORTIE | E21: 0 | F21: =C21+30 -> 40012 | G21: 0 | H21: 0 | I21: TRUE | J21: 1524 | K21: FALSE | L21: FALSE | M21: 0 | N21: 6 | O21: =DATEDIF(C21,DateFin,"d") -> 880 | P21: =DATEDIF(F21,DateFin,"d") -> 850 | Q21: =TODAY()-O21 -> 45175 | R21: =TODAY()-P21 -> 45205
A22: 2403 | B22: 1095 | C22: 39984 | D22: SORTIE | E22: 0 | F22: 40025 | G22: 0 | H22: 0 | I22: TRUE | J22: 1524 | K22: FALSE | L22: FALSE | M22: 0 | N22: 6 | O22: =DATEDIF(C22,DateFin,"d") -> 878 | P22: =DATEDIF(F22,DateFin,"d") -> 837 | Q22: =TODAY()-O22 -> 45177 | R22: =TODAY()-P22 -> 45218
A23: 2404 | B23: 2937 | C23: 40002 | D23: SORTIE | E23: 0 | F23: =C23+30 -> 40032 | G23: 0 | H23: 0 | I23: TRUE | J23: 1524 | K23: FALSE | L23: FALSE | M23: 0 | N23: 6 | O23: =DATEDIF(C23,DateFin,"d") -> 860 | P23: =DATEDIF(F23,DateFin,"d") -> 830 | Q23: =TODAY()-O23 -> 45195 | R23: =TODAY()-P23 -> 45225
A24: 2405 | B24: 798 | C24: 40002 | D24: SORTIE | E24: 0 | F24: =C24+30 -> 40032 | G24: 0 | H24: 0 | I24: TRUE | J24: 1524 | K24: FALSE | L24: FALSE | M24: 0 | N24: 6 | O24: =DATEDIF(C24,DateFin,"d") -> 860 | P24: =DATEDIF(F24,DateFin,"d") -> 830 | Q24: =TODAY()-O24 -> 45195 | R24: =TODAY()-P24 -> 45225
A25: 2406 | B25: 1472 | C25: 40011 | D25: SORTIE | E25: 0 | F25: =C25+30 -> 40041 | G25: 0 | H25: 0 | I25: TRUE | J25: 640 | K25: TRUE | L25: FALSE | M25: 0 | N25: 6 | O25: =DATEDIF(C25,DateFin,"d") -> 851 | P25: =DATEDIF(F25,DateFin,"d") -> 821 | Q25: =TODAY()-O25 -> 45204 | R25: =TODAY()-P25 -> 45234
A26: 2407 | B26: 1277 | C26: 40015 | D26: SORTIE | E26: 0 | F26: =C26+30 -> 40045 | G26: 30 | H26: 0.03 | I26: TRUE | J26: 1524 | K26: FALSE | L26: FALSE | M26: 0 | N26: 6 | O26: =DATEDIF(C26,DateFin,"d") -> 847 | P26: =DATEDIF(F26,DateFin,"d") -> 817 | Q26: =TODAY()-O26 -> 45208 | R26: =TODAY()-P26 -> 45238
A27: 2408 | B27: 3624 | C27: 40016 | D27: SORTIE | E27: 0 | F27: =C27+30 -> 40046 | G27: 0 | H27: 0 | I27: TRUE | J27: 1524 | K27: FALSE | L27: FALSE | M27: 0 | N27: 6 | O27: =DATEDIF(C27,DateFin,"d") -> 846 | P27: =DATEDIF(F27,DateFin,"d") -> 816 | Q27: =TODAY()-O27 -> 45209 | R27: =TODAY()-P27 -> 45239
A28: 2409 | B28: 3638 | C28: 40022 | D28: SORTIE | E28: 0 | F28: =C28+30 -> 40052 | G28: 22 | H28: 0 | I28: TRUE | J28: 1524 | K28: FALSE | L28: FALSE | M28: 0 | N28: 6 | O28: =DATEDIF(C28,DateFin,"d") -> 840 | P28: =DATEDIF(F28,DateFin,"d") -> 810 | Q28: =TODAY()-O28 -> 45215 | R28: =TODAY()-P28 -> 45245
A29: 2410 | B29: 1559 | C29: 40022 | D29: SORTIE | E29: 0 | F29: =C29+30 -> 40052 | G29: 19 | H29: 0 | I29: TRUE | J29: 1524 | K29: TRUE | L29: FALSE | M29: 0 | N29: 6 | O29: =DATEDIF(C29,DateFin,"d") -> 840 | P29: =DATEDIF(F29,DateFin,"d") -> 810 | Q29: =TODAY()-O29 -> 45215 | R29: =TODAY()-P29 -> 45245
A30: 2411 | B30: 2971 | C30: 40025 | D30: SORTIE | E30: 0 | F30: =C30+30 -> 40055 | G30: 0 | H30: 0 | I30: TRUE | J30: 640 | K30: TRUE | L30: FALSE | M30: 0 | N30: 6 | O30: =DATEDIF(C30,DateFin,"d") -> 837 | P30: =DATEDIF(F30,DateFin,"d") -> 807 | Q30: =TODAY()-O30 -> 45218 | R30: =TODAY()-P30 -> 45248
A31: 2412 | B31: 3620 | C31: 40060 | D31: SORTIE | E31: 0 | F31: =C31+30 -> 40090 | G31: 0 | H31: 0.03 | I31: TRUE | J31: 1524 | K31: FALSE | L31: FALSE | M31: 0 | N31: 6 | O31: =DATEDIF(C31,DateFin,"d") -> 802 | P31: =DATEDIF(F31,DateFin,"d") -> 772 | Q31: =TODAY()-O31 -> 45253 | R31: =TODAY()-P31 -> 45283
A32: 2413 | B32: 2421 | C32: 40078 | D32: SORTIE | E32: 0 | F32: =C32+30 -> 40108 | G32: 0 | H32: 0 | I32: TRUE | J32: 1524 | K32: FALSE | L32: FALSE | M32: 0 | N32: 6 | O32: =DATEDIF(C32,DateFin,"d") -> 784 | P32: =DATEDIF(F32,DateFin,"d") -> 754 | Q32: =TODAY()-O32 -> 45271 | R32: =TODAY()-P32 -> 45301
A33: 2414 | B33: 3659 | C33: 40074 | D33: SORTIE | E33: 0 | F33: =C33+30 -> 40104 | G33: 85 | H33: 0 | I33: TRUE | J33: 1524 | K33: FALSE | L33: FALSE | M33: 0 | N33: 6 | O33: =DATEDIF(C33,DateFin,"d") -> 788 | P33: =DATEDIF(F33,DateFin,"d") -> 758 | Q33: =TODAY()-O33 -> 45267 | R33: =TODAY()-P33 -> 45297
A34: 2415 | B34: 2829 | C34: 40088 | D34: SORTIE | E34: 500 | F34: =C34+30 -> 40118 | G34: 69 | H34: 0 | I34: TRUE | J34: 1524 | K34: FALSE | L34: FALSE | M34: 0 | N34: 6 | O34: =DATEDIF(C34,DateFin,"d") -> 774 | P34: =DATEDIF(F34,DateFin,"d") -> 744 | Q34: =TODAY()-O34 -> 45281 | R34: =TODAY()-P34 -> 45311
... A224: 2605 | B224: 798 | C224: 40757 | D224: SORTIE | E224: 0 | F224: =C224+30 -> 40787 | G224: 0 | H224: 0.3 | I224: FALSE | J224: 1524 | K224: FALSE | L224: FALSE | M224: 0 | N224: 6 | O224: =DATEDIF(C224,DateFin,"d") -> 105 | P224: =DATEDIF(F224,DateFin,"d") -> 75 | Q224: =TODAY()-O224 -> 45950 | R224: =TODAY()-P224 -> 45980
A225: 2606 | B225: 2829 | C225: 40764 | D225: SORTIE | E225: 0 | F225: =C225+60 -> 40824 | G225: 0 | H225: 0 | I225: TRUE | J225: 1524 | K225: FALSE | L225: FALSE | M225: 0 | N225: 6 | O225: =DATEDIF(C225,DateFin,"d") -> 98 | P225: =DATEDIF(F225,DateFin,"d") -> 38 | Q225: =TODAY()-O225 -> 45957 | R225: =TODAY()-P225 -> 46017
A226: 2607 | B226: 2962 | C226: 40771 | D226: SORTIE | E226: 0 | F226: =C226+30 -> 40801 | G226: 46 | H226: 0.2 | I226: TRUE | J226: 1524 | K226: TRUE | L226: FALSE | M226: 0 | N226: 6 | O226: =DATEDIF(C226,DateFin,"d") -> 91 | P226: =DATEDIF(F226,DateFin,"d") -> 61 | Q226: =TODAY()-O226 -> 45964 | R226: =TODAY()-P226 -> 45994
A227: 2608 | B227: 1156 | C227: 40778 | D227: SORTIE | E227: 0 | F227: =C227+30 -> 40808 | G227: 29.5 | H227: 0 | I227: TRUE | J227: 1524 | K227: FALSE | L227: FALSE | M227: 0 | N227: 6 | O227: =DATEDIF(C227,DateFin,"d") -> 84 | P227: =DATEDIF(F227,DateFin,"d") -> 54 | Q227: =TODAY()-O227 -> 45971 | R227: =TODAY()-P227 -> 46001
A228: 2609 | B228: 2478 | C228: 40785 | D228: SORTIE | E228: 0 | F228: =C228+30 -> 40815 | G228: 14.5 | H228: 0 | I228: FALSE | J228: 640 | K228: FALSE | L228: FALSE | M228: 0 | N228: 6 | O228: =DATEDIF(C228,DateFin,"d") -> 77 | P228: =DATEDIF(F228,DateFin,"d") -> 47 | Q228: =TODAY()-O228 -> 45978 | R228: =TODAY()-P228 -> 46008
A229: 2610 | B229: 2319 | C229: 40792 | D229: SORTIE | E229: 0 | F229: =C229+30 -> 40822 | G229: 0 | H229: 0.3 | I229: TRUE | J229: 1524 | K229: FALSE | L229: FALSE | M229: 0 | N229: 6 | O229: =DATEDIF(C229,DateFin,"d") -> 70 | P229: =DATEDIF(F229,DateFin,"d") -> 40 | Q229: =TODAY()-O229 -> 45985 | R229: =TODAY()-P229 -> 46015
A230: 2611 | B230: 2937 | C230: 40799 | D230: SORTIE | E230: 0 | F230: =C230+60 -> 40859 | G230: 0 | H230: 0.3 | I230: FALSE | J230: 1524 | K230: FALSE | L230: FALSE | M230: 0 | N230: 6 | O230: =DATEDIF(C230,DateFin,"d") -> 63 | P230: =DATEDIF(F230,DateFin,"d") -> 3 | Q230: =TODAY()-O230 -> 45992 | R230: =TODAY()-P230 -> 46052
A231: 2612 | B231: 1482 | C231: 40806 | D231: SORTIE | E231: 0 | F231: =C231+30 -> 40836 | G231: 36 | H231: 0 | I231: TRUE | J231: 640 | K231: TRUE | L231: FALSE | M231: 0 | N231: 6 | O231: =DATEDIF(C231,DateFin,"d") -> 56 | P231: =DATEDIF(F231,DateFin,"d") -> 26 | Q231: =TODAY()-O231 -> 45999 | R231: =TODAY()-P231 -> 46029
A232: 2613 | B232: 798 | C232: 40813 | D232: SORTIE | E232: 0 | F232: =C232+30 -> 40843 | G232: 0 | H232: 0.3 | I232: FALSE | J232: 1524 | K232: FALSE | L232: FALSE | M232: 0 | N232: 6 | O232: =DATEDIF(C232,DateFin,"d") -> 49 | P232: =DATEDIF(F232,DateFin,"d") -> 19 | Q232: =TODAY()-O232 -> 46006 | R232: =TODAY()-P232 -> 46036
A233: 2614 | B233: 798 | C233: 40820 | D233: SORTIE | E233: 0 | F233: =C233+60 -> 40880 | G233: 0 | H233: 0 | I233: TRUE | J233: 1524 | K233: TRUE | L233: FALSE | M233: 0 | N233: 6 | O233: =DATEDIF(C233,DateFin,"d") -> 42 | P233: =O233-30 -> 12 | Q233: =TODAY()-O233 -> 46013 | R233: =TODAY()-P233 -> 46043
A234: 2615 | B234: 27 | C234: 40827 | D234: SORTIE | E234: 0 | F234: =C234+30 -> 40857 | G234: 0 | H234: 0.2 | I234: TRUE | J234: 1524 | K234: FALSE | L234: FALSE | M234: 0 | N234: 6 | O234: =DATEDIF(C234,DateFin,"d") -> 35 | P234: =O234-30 -> 5 | Q234: =TODAY()-O234 -> 46020 | R234: =TODAY()-P234 -> 46050
A235: 2616 | B235: 3647 | C235: 40834 | D235: SORTIE | E235: 0 | F235: =C235+30 -> 40864 | G235: 19 | H235: 0 | I235: TRUE | J235: 1524 | K235: FALSE | L235: FALSE | M235: 0 | N235: 6 | O235: =DATEDIF(C235,DateFin,"d") -> 28 | P235: =O235-30 -> -2 | Q235: =TODAY()-O235 -> 46027 | R235: =TODAY()-P235 -> 46057
...

Sheet FacturesCALC (4)
A1: NumFacture | B1: NumClient | C1: NO_Datefacture | D1: Type | E1: Acompte | F1: NO_DateEcheance | G1: Frais de Port | H1: Escompte | I1: Facture Réglée | J1: Vendeur | K1: Commission VRP réglée | L1: Avoir | M1: RemRelance | N1: CommUnitaire | O1: NO_Decalage_Date_fact | P1: NO_Decalage_DateEch | Q1: Date Facture | R1: Date Echeance Fact
A2: 2383 | B2: 1745 | C2: 39836 | D2: SORTIE | E2: 0 | F2: 39872 | G2: 0 | H2: 0 | I2: TRUE | J2: 1524 | K2: FALSE | L2: FALSE | M2: 0 | N2: 6 | O2: =DATEDIF(C2,DateFin,"d") -> 1026 | P2: =DATEDIF(F2,DateFin,"d") -> 990 | Q2: =TODAY()-O2 -> 45029 | R2: =TODAY()-P2 -> 45065
A3: 2384 | B3: 707 | C3: 39837 | D3: SORTIE | E3: 0 | F3: =C3+30 -> 39867 | G3: 0 | H3: 0 | I3: TRUE | J3: 1524 | K3: FALSE | L3: FALSE | M3: 0 | N3: 6 | O3: =DATEDIF(C3,DateFin,"d") -> 1025 | P3: =DATEDIF(F3,DateFin,"d") -> 995 | Q3: =TODAY()-O3 -> 45030 | R3: =TODAY()-P3 -> 45060
A4: 2385 | B4: 2937 | C4: 39842 | D4: SORTIE | E4: 0 | F4: =C4+30 -> 39872 | G4: 0 | H4: 0 | I4: TRUE | J4: 1524 | K4: FALSE | L4: FALSE | M4: 0 | N4: 6 | O4: =DATEDIF(C4,DateFin,"d") -> 1020 | P4: =DATEDIF(F4,DateFin,"d") -> 990 | Q4: =TODAY()-O4 -> 45035 | R4: =TODAY()-P4 -> 45065
A5: 2386 | B5: 3647 | C5: 39844 | D5: SORTIE | E5: 0 | F5: =C5+30 -> 39874 | G5: 0 | H5: 0 | I5: TRUE | J5: 640 | K5: TRUE | L5: FALSE | M5: 0 | N5: 6 | O5: =DATEDIF(C5,DateFin,"d") -> 1018 | P5: =DATEDIF(F5,DateFin,"d") -> 988 | Q5: =TODAY()-O5 -> 45037 | R5: =TODAY()-P5 -> 45067
A6: 2387 | B6: 2952 | C6: 39844 | D6: SORTIE | E6: 0 | F6: =C6+30 -> 39874 | G6: 30 | H6: 0.03 | I6: TRUE | J6: 1524 | K6: FALSE | L6: FALSE | M6: 0 | N6: 6 | O6: =DATEDIF(C6,DateFin,"d") -> 1018 | P6: =DATEDIF(F6,DateFin,"d") -> 988 | Q6: =TODAY()-O6 -> 45037 | R6: =TODAY()-P6 -> 45067
A7: 2388 | B7: 933 | C7: 39848 | D7: SORTIE | E7: 0 | F7: =C7+30 -> 39878 | G7: 0 | H7: 0 | I7: TRUE | J7: 1524 | K7: FALSE | L7: FALSE | M7: 0 | N7: 6 | O7: =DATEDIF(C7,DateFin,"d") -> 1014 | P7: =DATEDIF(F7,DateFin,"d") -> 984 | Q7: =TODAY()-O7 -> 45041 | R7: =TODAY()-P7 -> 45071
A8: 2389 | B8: 3005 | C8: 39856 | D8: SORTIE | E8: 0 | F8: =C8+30 -> 39886 | G8: 22 | H8: 0 | I8: TRUE | J8: 1524 | K8: FALSE | L8: FALSE | M8: 0 | N8: 6 | O8: =DATEDIF(C8,DateFin,"d") -> 1006 | P8: =DATEDIF(F8,DateFin,"d") -> 976 | Q8: =TODAY()-O8 -> 45049 | R8: =TODAY()-P8 -> 45079
A9: 2390 | B9: 2937 | C9: 39864 | D9: SORTIE | E9: 0 | F9: =C9+30 -> 39894 | G9: 19 | H9: 0 | I9: TRUE | J9: 1524 | K9: TRUE | L9: FALSE | M9: 0 | N9: 6 | O9: =DATEDIF(C9,DateFin,"d") -> 998 | P9: =DATEDIF(F9,DateFin,"d") -> 968 | Q9: =TODAY()-O9 -> 45057 | R9: =TODAY()-P9 -> 45087
A10: 2391 | B10: 2971 | C10: 39872 | D10: SORTIE | E10: 0 | F10: =C10+30 -> 39902 | G10: 0 | H10: 0 | I10: TRUE | J10: 640 | K10: TRUE | L10: FALSE | M10: 0 | N10: 6 | O10: =DATEDIF(C10,DateFin,"d") -> 990 | P10: =DATEDIF(F10,DateFin,"d") -> 960 | Q10: =TODAY()-O10 -> 45065 | R10: =TODAY()-P10 -> 45095
A11: 2392 | B11: 3620 | C11: 39880 | D11: SORTIE | E11: 0 | F11: =C11+30 -> 39910 | G11: 0 | H11: 0.03 | I11: TRUE | J11: 1524 | K11: FALSE | L11: FALSE | M11: 0 | N11: 6 | O11: =DATEDIF(C11,DateFin,"d") -> 982 | P11: =DATEDIF(F11,DateFin,"d") -> 952 | Q11: =TODAY()-O11 -> 45073 | R11: =TODAY()-P11 -> 45103
A12: 2393 | B12: 2421 | C12: 39888 | D12: SORTIE | E12: 0 | F12: =C12+30 -> 39918 | G12: 0 | H12: 0 | I12: TRUE | J12: 1524 | K12: FALSE | L12: FALSE | M12: 0 | N12: 6 | O12: =DATEDIF(C12,DateFin,"d") -> 974 | P12: =DATEDIF(F12,DateFin,"d") -> 944 | Q12: =TODAY()-O12 -> 45081 | R12: =TODAY()-P12 -> 45111
A13: 2394 | B13: 3659 | C13: 39896 | D13: SORTIE | E13: 0 | F13: =C13+30 -> 39926 | G13: 85 | H13: 0 | I13: TRUE | J13: 1524 | K13: FALSE | L13: FALSE | M13: 0 | N13: 6 | O13: =DATEDIF(C13,DateFin,"d") -> 966 | P13: =DATEDIF(F13,DateFin,"d") -> 936 | Q13: =TODAY()-O13 -> 45089 | R13: =TODAY()-P13 -> 45119
A14: 2395 | B14: 1277 | C14: 39904 | D14: SORTIE | E14: 500 | F14: =C14+30 -> 39934 | G14: 69 | H14: 0 | I14: TRUE | J14: 1524 | K14: FALSE | L14: FALSE | M14: 0 | N14: 6 | O14: =DATEDIF(C14,DateFin,"d") -> 958 | P14: =DATEDIF(F14,DateFin,"d") -> 928 | Q14: =TODAY()-O14 -> 45097 | R14: =TODAY()-P14 -> 45127
... A21: 2402 | B21: 2937 | C21: 39982 | D21: SORTIE | E21: 0 | F21: =C21+30 -> 40012 | G21: 0 | H21: 0 | I21: TRUE | J21: 1524 | K21: FALSE | L21: FALSE | M21: 0 | N21: 6 | O21: =DATEDIF(C21,DateFin,"d") -> 880 | P21: =DATEDIF(F21,DateFin,"d") -> 850 | Q21: =TODAY()-O21 -> 45175 | R21: =TODAY()-P21 -> 45205
A22: 2403 | B22: 1095 | C22: 39984 | D22: SORTIE | E22: 0 | F22: 40025 | G22: 0 | H22: 0 | I22: TRUE | J22: 1524 | K22: FALSE | L22: FALSE | M22: 0 | N22: 6 | O22: =DATEDIF(C22,DateFin,"d") -> 878 | P22: =DATEDIF(F22,DateFin,"d") -> 837 | Q22: =TODAY()-O22 -> 45177 | R22: =TODAY()-P22 -> 45218
A23: 2404 | B23: 2937 | C23: 40002 | D23: SORTIE | E23: 0 | F23: =C23+30 -> 40032 | G23: 0 | H23: 0 | I23: TRUE | J23: 1524 | K23: FALSE | L23: FALSE | M23: 0 | N23: 6 | O23: =DATEDIF(C23,DateFin,"d") -> 860 | P23: =DATEDIF(F23,DateFin,"d") -> 830 | Q23: =TODAY()-O23 -> 45195 | R23: =TODAY()-P23 -> 45225
A24: 2405 | B24: 798 | C24: 40002 | D24: SORTIE | E24: 0 | F24: =C24+30 -> 40032 | G24: 0 | H24: 0 | I24: TRUE | J24: 1524 | K24: FALSE | L24: FALSE | M24: 0 | N24: 6 | O24: =DATEDIF(C24,DateFin,"d") -> 860 | P24: =DATEDIF(F24,DateFin,"d") -> 830 | Q24: =TODAY()-O24 -> 45195 | R24: =TODAY()-P24 -> 45225
A25: 2406 | B25: 1472 | C25: 40011 | D25: SORTIE | E25: 0 | F25: =C25+30 -> 40041 | G25: 0 | H25: 0 | I25: TRUE | J25: 640 | K25: TRUE | L25: FALSE | M25: 0 | N25: 6 | O25: =DATEDIF(C25,DateFin,"d") -> 851 | P25: =DATEDIF(F25,DateFin,"d") -> 821 | Q25: =TODAY()-O25 -> 45204 | R25: =TODAY()-P25 -> 45234
A26: 2407 | B26: 1277 | C26: 40015 | D26: SORTIE | E26: 0 | F26: =C26+30 -> 40045 | G26: 30 | H26: 0.03 | I26: TRUE | J26: 1524 | K26: FALSE | L26: FALSE | M26: 0 | N26: 6 | O26: =DATEDIF(C26,DateFin,"d") -> 847 | P26: =DATEDIF(F26,DateFin,"d") -> 817 | Q26: =TODAY()-O26 -> 45208 | R26: =TODAY()-P26 -> 45238
A27: 2408 | B27: 3624 | C27: 40016 | D27: SORTIE | E27: 0 | F27: =C27+30 -> 40046 | G27: 0 | H27: 0 | I27: TRUE | J27: 1524 | K27: FALSE | L27: FALSE | M27: 0 | N27: 6 | O27: =DATEDIF(C27,DateFin,"d") -> 846 | P27: =DATEDIF(F27,DateFin,"d") -> 816 | Q27: =TODAY()-O27 -> 45209 | R27: =TODAY()-P27 -> 45239
A28: 2409 | B28: 3638 | C28: 40022 | D28: SORTIE | E28: 0 | F28: =C28+30 -> 40052 | G28: 22 | H28: 0 | I28: TRUE | J28: 1524 | K28: FALSE | L28: FALSE | M28: 0 | N28: 6 | O28: =DATEDIF(C28,DateFin,"d") -> 840 | P28: =DATEDIF(F28,DateFin,"d") -> 810 | Q28: =TODAY()-O28 -> 45215 | R28: =TODAY()-P28 -> 45245
A29: 2410 | B29: 1559 | C29: 40022 | D29: SORTIE | E29: 0 | F29: =C29+30 -> 40052 | G29: 19 | H29: 0 | I29: TRUE | J29: 1524 | K29: TRUE | L29: FALSE | M29: 0 | N29: 6 | O29: =DATEDIF(C29,DateFin,"d") -> 840 | P29: =DATEDIF(F29,DateFin,"d") -> 810 | Q29: =TODAY()-O29 -> 45215 | R29: =TODAY()-P29 -> 45245
A30: 2411 | B30: 2971 | C30: 40025 | D30: SORTIE | E30: 0 | F30: =C30+30 -> 40055 | G30: 0 | H30: 0 | I30: TRUE | J30: 640 | K30: TRUE | L30: FALSE | M30: 0 | N30: 6 | O30: =DATEDIF(C30,DateFin,"d") -> 837 | P30: =DATEDIF(F30,DateFin,"d") -> 807 | Q30: =TODAY()-O30 -> 45218 | R30: =TODAY()-P30 -> 45248
A31: 2412 | B31: 3620 | C31: 40060 | D31: SORTIE | E31: 0 | F31: =C31+30 -> 40090 | G31: 0 | H31: 0.03 | I31: TRUE | J31: 1524 | K31: FALSE | L31: FALSE | M31: 0 | N31: 6 | O31: =DATEDIF(C31,DateFin,"d") -> 802 | P31: =DATEDIF(F31,DateFin,"d") -> 772 | Q31: =TODAY()-O31 -> 45253 | R31: =TODAY()-P31 -> 45283
A32: 2413 | B32: 2421 | C32: 40078 | D32: SORTIE | E32: 0 | F32: =C32+30 -> 40108 | G32: 0 | H32: 0 | I32: TRUE | J32: 1524 | K32: FALSE | L32: FALSE | M32: 0 | N32: 6 | O32: =DATEDIF(C32,DateFin,"d") -> 784 | P32: =DATEDIF(F32,DateFin,"d") -> 754 | Q32: =TODAY()-O32 -> 45271 | R32: =TODAY()-P32 -> 45301
A33: 2414 | B33: 3659 | C33: 40074 | D33: SORTIE | E33: 0 | F33: =C33+30 -> 40104 | G33: 85 | H33: 0 | I33: TRUE | J33: 1524 | K33: FALSE | L33: FALSE | M33: 0 | N33: 6 | O33: =DATEDIF(C33,DateFin,"d") -> 788 | P33: =DATEDIF(F33,DateFin,"d") -> 758 | Q33: =TODAY()-O33 -> 45267 | R33: =TODAY()-P33 -> 45297
A34: 2415 | B34: 2829 | C34: 40088 | D34: SORTIE | E34: 500 | F34: =C34+30 -> 40118 | G34: 69 | H34: 0 | I34: TRUE | J34: 1524 | K34: FALSE | L34: FALSE | M34: 0 | N34: 6 | O34: =DATEDIF(C34,DateFin,"d") -> 774 | P34: =DATEDIF(F34,DateFin,"d") -> 744 | Q34: =TODAY()-O34 -> 45281 | R34: =TODAY()-P34 -> 45311
... A224: 2605 | B224: 798 | C224: 40757 | D224: SORTIE | E224: 0 | F224: =C224+30 -> 40787 | G224: 0 | H224: 0.3 | I224: FALSE | J224: 1524 | K224: FALSE | L224: FALSE | M224: 0 | N224: 6 | O224: =DATEDIF(C224,DateFin,"d") -> 105 | P224: =DATEDIF(F224,DateFin,"d") -> 75 | Q224: =TODAY()-O224 -> 45950 | R224: =TODAY()-P224 -> 45980
A225: 2606 | B225: 2829 | C225: 40764 | D225: SORTIE | E225: 0 | F225: =C225+60 -> 40824 | G225: 0 | H225: 0 | I225: TRUE | J225: 1524 | K225: FALSE | L225: FALSE | M225: 0 | N225: 6 | O225: =DATEDIF(C225,DateFin,"d") -> 98 | P225: =DATEDIF(F225,DateFin,"d") -> 38 | Q225: =TODAY()-O225 -> 45957 | R225: =TODAY()-P225 -> 46017
A226: 2607 | B226: 2962 | C226: 40771 | D226: SORTIE | E226: 0 | F226: =C226+30 -> 40801 | G226: 46 | H226: 0.2 | I226: TRUE | J226: 1524 | K226: TRUE | L226: FALSE | M226: 0 | N226: 6 | O226: =DATEDIF(C226,DateFin,"d") -> 91 | P226: =DATEDIF(F226,DateFin,"d") -> 61 | Q226: =TODAY()-O226 -> 45964 | R226: =TODAY()-P226 -> 45994
A227: 2608 | B227: 1156 | C227: 40778 | D227: SORTIE | E227: 0 | F227: =C227+30 -> 40808 | G227: 29.5 | H227: 0 | I227: TRUE | J227: 1524 | K227: FALSE | L227: FALSE | M227: 0 | N227: 6 | O227: =DATEDIF(C227,DateFin,"d") -> 84 | P227: =DATEDIF(F227,DateFin,"d") -> 54 | Q227: =TODAY()-O227 -> 45971 | R227: =TODAY()-P227 -> 46001
A228: 2609 | B228: 2478 | C228: 40785 | D228: SORTIE | E228: 0 | F228: =C228+30 -> 40815 | G228: 14.5 | H228: 0 | I228: FALSE | J228: 640 | K228: FALSE | L228: FALSE | M228: 0 | N228: 6 | O228: =DATEDIF(C228,DateFin,"d") -> 77 | P228: =DATEDIF(F228,DateFin,"d") -> 47 | Q228: =TODAY()-O228 -> 45978 | R228: =TODAY()-P228 -> 46008
A229: 2610 | B229: 2319 | C229: 40792 | D229: SORTIE | E229: 0 | F229: =C229+30 -> 40822 | G229: 0 | H229: 0.3 | I229: TRUE | J229: 1524 | K229: FALSE | L229: FALSE | M229: 0 | N229: 6 | O229: =DATEDIF(C229,DateFin,"d") -> 70 | P229: =DATEDIF(F229,DateFin,"d") -> 40 | Q229: =TODAY()-O229 -> 45985 | R229: =TODAY()-P229 -> 46015
A230: 2611 | B230: 2937 | C230: 40799 | D230: SORTIE | E230: 0 | F230: =C230+60 -> 40859 | G230: 0 | H230: 0.3 | I230: FALSE | J230: 1524 | K230: FALSE | L230: FALSE | M230: 0 | N230: 6 | O230: =DATEDIF(C230,DateFin,"d") -> 63 | P230: =DATEDIF(F230,DateFin,"d") -> 3 | Q230: =TODAY()-O230 -> 45992 | R230: =TODAY()-P230 -> 46052
A231: 2612 | B231: 1482 | C231: 40806 | D231: SORTIE | E231: 0 | F231: =C231+30 -> 40836 | G231: 36 | H231: 0 | I231: TRUE | J231: 640 | K231: TRUE | L231: FALSE | M231: 0 | N231: 6 | O231: =DATEDIF(C231,DateFin,"d") -> 56 | P231: =DATEDIF(F231,DateFin,"d") -> 26 | Q231: =TODAY()-O231 -> 45999 | R231: =TODAY()-P231 -> 46029
A232: 2613 | B232: 798 | C232: 40813 | D232: SORTIE | E232: 0 | F232: =C232+30 -> 40843 | G232: 0 | H232: 0.3 | I232: FALSE | J232: 1524 | K232: FALSE | L232: FALSE | M232: 0 | N232: 6 | O232: =DATEDIF(C232,DateFin,"d") -> 49 | P232: =DATEDIF(F232,DateFin,"d") -> 19 | Q232: =TODAY()-O232 -> 46006 | R232: =TODAY()-P232 -> 46036
A233: 2614 | B233: 798 | C233: 40820 | D233: SORTIE | E233: 0 | F233: =C233+60 -> 40880 | G233: 0 | H233: 0 | I233: TRUE | J233: 1524 | K233: TRUE | L233: FALSE | M233: 0 | N233: 6 | O233: =DATEDIF(C233,DateFin,"d") -> 42 | P233: =O233-30 -> 12 | Q233: =TODAY()-O233 -> 46013 | R233: =TODAY()-P233 -> 46043
A234: 2615 | B234: 27 | C234: 40827 | D234: SORTIE | E234: 0 | F234: =C234+30 -> 40857 | G234: 0 | H234: 0.2 | I234: TRUE | J234: 1524 | K234: FALSE | L234: FALSE | M234: 0 | N234: 6 | O234: =DATEDIF(C234,DateFin,"d") -> 35 | P234: =O234-30 -> 5 | Q234: =TODAY()-O234 -> 46020 | R234: =TODAY()-P234 -> 46050
A235: 2616 | B235: 3647 | C235: 40834 | D235: SORTIE | E235: 0 | F235: =C235+30 -> 40864 | G235: 19 | H235: 0 | I235: TRUE | J235: 1524 | K235: FALSE | L235: FALSE | M235: 0 | N235: 6 | O235: =DATEDIF(C235,DateFin,"d") -> 28 | P235: =O235-30 -> -2 | Q235: =TODAY()-O235 -> 46027 | R235: =TODAY()-P235 -> 46057
...

Sheet Factures
A1: NumFacture | B1: NumClient | C1: Type | D1: Acompte | E1: Frais de Port | F1: Escompte | G1: Facture Réglée | H1: Vendeur | I1: Commission VRP réglée | J1: Avoir | K1: RemRelance | L1: CommUnitaire | M1: Date Facture | N1: Date Echeance Fact
A2: 2383 | B2: 1745 | C2: SORTIE | D2: 0 | E2: 0 | F2: 0 | G2: TRUE | H2: 1524 | I2: FALSE | J2: FALSE | K2: 0 | L2: 6 | M2: 45029 | N2: 45065
A3: 2384 | B3: 707 | C3: SORTIE | D3: 0 | E3: 0 | F3: 0 | G3: TRUE | H3: 1524 | I3: FALSE | J3: FALSE | K3: 0 | L3: 6 | M3: 45030 | N3: 45060
A4: 2385 | B4: 2937 | C4: SORTIE | D4: 0 | E4: 0 | F4: 0 | G4: TRUE | H4: 1524 | I4: FALSE | J4: FALSE | K4: 0 | L4: 6 | M4: 45035 | N4: 45065
A5: 2386 | B5: 3647 | C5: SORTIE | D5: 0 | E5: 0 | F5: 0 | G5: TRUE | H5: 640 | I5: TRUE | J5: FALSE | K5: 0 | L5: 6 | M5: 45037 | N5: 45067
A6: 2387 | B6: 2952 | C6: SORTIE | D6: 0 | E6: 30 | F6: 0.03 | G6: TRUE | H6: 1524 | I6: FALSE | J6: FALSE | K6: 0 | L6: 6 | M6: 45037 | N6: 45067
A7: 2388 | B7: 933 | C7: SORTIE | D7: 0 | E7: 0 | F7: 0 | G7: TRUE | H7: 1524 | I7: FALSE | J7: FALSE | K7: 0 | L7: 6 | M7: 45041 | N7: 45071
A8: 2389 | B8: 3005 | C8: SORTIE | D8: 0 | E8: 22 | F8: 0 | G8: TRUE | H8: 1524 | I8: FALSE | J8: FALSE | K8: 0 | L8: 6 | M8: 45049 | N8: 45079
A9: 2390 | B9: 2937 | C9: SORTIE | D9: 0 | E9: 19 | F9: 0 | G9: TRUE | H9: 1524 | I9: TRUE | J9: FALSE | K9: 0 | L9: 6 | M9: 45057 | N9: 45087
A10: 2391 | B10: 2971 | C10: SORTIE | D10: 0 | E10: 0 | F10: 0 | G10: TRUE | H10: 640 | I10: TRUE | J10: FALSE | K10: 0 | L10: 6 | M10: 45065 | N10: 45095
A11: 2392 | B11: 3620 | C11: SORTIE | D11: 0 | E11: 0 | F11: 0.03 | G11: TRUE | H11: 1524 | I11: FALSE | J11: FALSE | K11: 0 | L11: 6 | M11: 45073 | N11: 45103
A12: 2393 | B12: 2421 | C12: SORTIE | D12: 0 | E12: 0 | F12: 0 | G12: TRUE | H12: 1524 | I12: FALSE | J12: FALSE | K12: 0 | L12: 6 | M12: 45081 | N12: 45111
A13: 2394 | B13: 3659 | C13: SORTIE | D13: 0 | E13: 85 | F13: 0 | G13: TRUE | H13: 1524 | I13: FALSE | J13: FALSE | K13: 0 | L13: 6 | M13: 45089 | N13: 45119
... A239: 2620 | B239: 1395 | C239: SORTIE | D239: 0 | E239: 0 | F239: 0 | G239: FALSE | H239: 1524 | I239: FALSE | J239: FALSE | K239: 0 | L239: 6 | M239: 46055 | N239: 46085
